Workbook

Sheet Dashboard & GPA
A1: Seneca Polytechnic — Computer Systems Technology (CTY)
A2: Semester 3 Academic Performance Dashboard, Hurdle Verification & Official Seneca 4.0 GPA Calculator
A3: 💡 FAST NAVIGATION: Click any blue Course Code below to jump directly to that course sheet. Enter your grades to see GPA and totals update in real time.
A5: CUMULATIVE GPA | C5: PROJECTED GPA | E5: CURRENT OVERALL AVG | G5: TECHNICAL CORE AVG | I5: TOTAL TERM CREDITS
A6: =IF(SUMIF(I11:I17, ">=0", C11:C17)>0, ROUND(SUM(K11:K17)/SUMIF(I11:I17, ">=0", C11:C17), 2), "--") | C6: =IF(SUMIF(G11:G17, ">0", C11:C17)>0, ROUND(SUM(L11:L17)/SUMIF(G11:G17, ">0", C11:C17), 2), "--") | E6: =IF(SUMIF(F11:F17, ">0", C11:C17)>0, ROUND(SUM(M11:M17)/SUMIF(F11:F17, ">0", C11:C17), 1), "--") | G6: =IF(SUM(O11:O17)>0, ROUND(SUM(N11:N17)/SUM(O11:O17), 1), "--") | I6: =SUM(C11:C17)
A7: Graded Courses to Date | C7: Estimated Final Term GPA | E7: Credit-Weighted Average | G7: 5 Computing Core Courses | I7: 7 Enrolled Courses
A10: Course Code | B10: Course Title | C10: Credits | D10: Classification | E10: Completed % | F10: Current Avg % | G10: Projected Final % | H10: Letter Grade | I10: GPA Points | J10: Hurdle Status
A11: =HYPERLINK("#'CSN305'!A1", "CSN305") | B11: Virtualization and Cloud Infrastructure | C11: 3 | D11: Technical Core | E11: ='CSN305'!A6 | F11: =IF('CSN305'!A6>0, 'CSN305'!E6, "") | G11: =IF('CSN305'!A6>0, 'CSN305'!G6, "") | H11: =IF(ISNUMBER(G11), IF(G11>=0.9, "A+", IF(G11>=0.8, "A", IF(G11>=0.75, "B+", IF(G11>=0.7, "B", IF(G11>=0.65, "C+", IF(G11>=0.6, "C", IF(G11>=0.55, "D+", IF(G11>=0.5, "D", "F")))))))), "--") | I11: =IF(H11="A+", 4.0, IF(H11="A", 4.0, IF(H11="B+", 3.5, IF(H11="B", 3.0, IF(H11="C+", 2.5, IF(H11="C", 2.0, IF(H11="D+", 1.5, IF(H11="D", 1.0, IF(H11="F", 0.0, ""))))))))) | J11: ='CSN305'!I6 | K11: =IF(ISNUMBER(I11), I11*C11, "") | L11: =IF(ISNUMBER(G11), IF(G11>=0.9, 4.0, IF(G11>=0.8, 4.0, IF(G11>=0.75, 3.5, IF(G11>=0.7, 3.0, IF(G11>=0.65, 2.5, IF(G11>=0.6, 2.0, IF(G11>=0.55, 1.5, IF(G11>=0.5, 1.0, 0.0))))))))*C11, "") | M11: =IF(AND(ISNUMBER(F11), F11>0), F11*C11, "") | N11: =IF(AND(D11="Technical Core", ISNUMBER(F11), F11>0), F11*C11, "") | O11: =IF(AND(D11="Technical Core", ISNUMBER(F11), F11>0), C11, "")
A12: =HYPERLINK("#'DAT330'!A1", "DAT330") | B12: Introduction to Databases | C12: 3 | D12: Technical Core | E12: ='DAT330'!A6 | F12: =IF('DAT330'!A6>0, 'DAT330'!E6, "") | G12: =IF('DAT330'!A6>0, 'DAT330'!G6, "") | H12: =IF(ISNUMBER(G12), IF(G12>=0.9, "A+", IF(G12>=0.8, "A", IF(G12>=0.75, "B+", IF(G12>=0.7, "B", IF(G12>=0.65, "C+", IF(G12>=0.6, "C", IF(G12>=0.55, "D+", IF(G12>=0.5, "D", "F")))))))), "--") | I12: =IF(H12="A+", 4.0, IF(H12="A", 4.0, IF(H12="B+", 3.5, IF(H12="B", 3.0, IF(H12="C+", 2.5, IF(H12="C", 2.0, IF(H12="D+", 1.5, IF(H12="D", 1.0, IF(H12="F", 0.0, ""))))))))) | J12: ='DAT330'!I6 | K12: =IF(ISNUMBER(I12), I12*C12, "") | L12: =IF(ISNUMBER(G12), IF(G12>=0.9, 4.0, IF(G12>=0.8, 4.0, IF(G12>=0.75, 3.5, IF(G12>=0.7, 3.0, IF(G12>=0.65, 2.5, IF(G12>=0.6, 2.0, IF(G12>=0.55, 1.5, IF(G12>=0.5, 1.0, 0.0))))))))*C12, "") | M12: =IF(AND(ISNUMBER(F12), F12>0), F12*C12, "") | N12: =IF(AND(D12="Technical Core", ISNUMBER(F12), F12>0), F12*C12, "") | O12: =IF(AND(D12="Technical Core", ISNUMBER(F12), F12>0), C12, "")
A13: =HYPERLINK("#'MST300'!A1", "MST300") | B13: Introduction to Microsoft Cloud Technologies | C13: 3 | D13: Technical Core | E13: ='MST300'!A6 | F13: =IF('MST300'!A6>0, 'MST300'!E6, "") | G13: =IF('MST300'!A6>0, 'MST300'!G6, "") | H13: =IF(ISNUMBER(G13), IF(G13>=0.9, "A+", IF(G13>=0.8, "A", IF(G13>=0.75, "B+", IF(G13>=0.7, "B", IF(G13>=0.65, "C+", IF(G13>=0.6, "C", IF(G13>=0.55, "D+", IF(G13>=0.5, "D", "F")))))))), "--") | I13: =IF(H13="A+", 4.0, IF(H13="A", 4.0, IF(H13="B+", 3.5, IF(H13="B", 3.0, IF(H13="C+", 2.5, IF(H13="C", 2.0, IF(H13="D+", 1.5, IF(H13="D", 1.0, IF(H13="F", 0.0, ""))))))))) | J13: ='MST300'!I6 | K13: =IF(ISNUMBER(I13), I13*C13, "") | L13: =IF(ISNUMBER(G13), IF(G13>=0.9, 4.0, IF(G13>=0.8, 4.0, IF(G13>=0.75, 3.5, IF(G13>=0.7, 3.0, IF(G13>=0.65, 2.5, IF(G13>=0.6, 2.0, IF(G13>=0.55, 1.5, IF(G13>=0.5, 1.0, 0.0))))))))*C13, "") | M13: =IF(AND(ISNUMBER(F13), F13>0), F13*C13, "") | N13: =IF(AND(D13="Technical Core", ISNUMBER(F13), F13>0), F13*C13, "") | O13: =IF(AND(D13="Technical Core", ISNUMBER(F13), F13>0), C13, "")
A14: =HYPERLINK("#'PSY262'!A1", "PSY262") | B14: Applied Psychology of Mindfulness | C14: 3 | D14: General Ed | E14: ='PSY262'!A6 | F14: =IF('PSY262'!A6>0, 'PSY262'!E6, "") | G14: =IF('PSY262'!A6>0, 'PSY262'!G6, "") | H14: =IF(ISNUMBER(G14), IF(G14>=0.9, "A+", IF(G14>=0.8, "A", IF(G14>=0.75, "B+", IF(G14>=0.7, "B", IF(G14>=0.65, "C+", IF(G14>=0.6, "C", IF(G14>=0.55, "D+", IF(G14>=0.5, "D", "F")))))))), "--") | I14: =IF(H14="A+", 4.0, IF(H14="A", 4.0, IF(H14="B+", 3.5, IF(H14="B", 3.0, IF(H14="C+", 2.5, IF(H14="C", 2.0, IF(H14="D+", 1.5, IF(H14="D", 1.0, IF(H14="F", 0.0, ""))))))))) | J14: ='PSY262'!I6 | K14: =IF(ISNUMBER(I14), I14*C14, "") | L14: =IF(ISNUMBER(G14), IF(G14>=0.9, 4.0, IF(G14>=0.8, 4.0, IF(G14>=0.75, 3.5, IF(G14>=0.7, 3.0, IF(G14>=0.65, 2.5, IF(G14>=0.6, 2.0, IF(G14>=0.55, 1.5, IF(G14>=0.5, 1.0, 0.0))))))))*C14, "") | M14: =IF(AND(ISNUMBER(F14), F14>0), F14*C14, "") | N14: =IF(AND(D14="Technical Core", ISNUMBER(F14), F14>0), F14*C14, "") | O14: =IF(AND(D14="Technical Core", ISNUMBER(F14), F14>0), C14, "")
A15: =HYPERLINK("#'SEC320'!A1", "SEC320") | B15: Incident Response and Computer Forensics | C15: 3 | D15: Technical Core | E15: ='SEC320'!A6 | F15: =IF('SEC320'!A6>0, 'SEC320'!E6, "") | G15: =IF('SEC320'!A6>0, 'SEC320'!G6, "") | H15: =IF(ISNUMBER(G15), IF(G15>=0.9, "A+", IF(G15>=0.8, "A", IF(G15>=0.75, "B+", IF(G15>=0.7, "B", IF(G15>=0.65, "C+", IF(G15>=0.6, "C", IF(G15>=0.55, "D+", IF(G15>=0.5, "D", "F")))))))), "--") | I15: =IF(H15="A+", 4.0, IF(H15="A", 4.0, IF(H15="B+", 3.5, IF(H15="B", 3.0, IF(H15="C+", 2.5, IF(H15="C", 2.0, IF(H15="D+", 1.5, IF(H15="D", 1.0, IF(H15="F", 0.0, ""))))))))) | J15: ='SEC320'!I6 | K15: =IF(ISNUMBER(I15), I15*C15, "") | L15: =IF(ISNUMBER(G15), IF(G15>=0.9, 4.0, IF(G15>=0.8, 4.0, IF(G15>=0.75, 3.5, IF(G15>=0.7, 3.0, IF(G15>=0.65, 2.5, IF(G15>=0.6, 2.0, IF(G15>=0.55, 1.5, IF(G15>=0.5, 1.0, 0.0))))))))*C15, "") | M15: =IF(AND(ISNUMBER(F15), F15>0), F15*C15, "") | N15: =IF(AND(D15="Technical Core", ISNUMBER(F15), F15>0), F15*C15, "") | O15: =IF(AND(D15="Technical Core", ISNUMBER(F15), F15>0), C15, "")
A16: =HYPERLINK("#'OPS345'!A1", "OPS345") | B16: Open System Application Server | C16: 3 | D16: Technical Core | E16: ='OPS345'!A6 | F16: =IF('OPS345'!A6>0, 'OPS345'!E6, "") | G16: =IF('OPS345'!A6>0, 'OPS345'!G6, "") | H16: =IF(ISNUMBER(G16), IF(G16>=0.9, "A+", IF(G16>=0.8, "A", IF(G16>=0.75, "B+", IF(G16>=0.7, "B", IF(G16>=0.65, "C+", IF(G16>=0.6, "C", IF(G16>=0.55, "D+", IF(G16>=0.5, "D", "F")))))))), "--") | I16: =IF(H16="A+", 4.0, IF(H16="A", 4.0, IF(H16="B+", 3.5, IF(H16="B", 3.0, IF(H16="C+", 2.5, IF(H16="C", 2.0, IF(H16="D+", 1.5, IF(H16="D", 1.0, IF(H16="F", 0.0, ""))))))))) | J16: ='OPS345'!I6 | K16: =IF(ISNUMBER(I16), I16*C16, "") | L16: =IF(ISNUMBER(G16), IF(G16>=0.9, 4.0, IF(G16>=0.8, 4.0, IF(G16>=0.75, 3.5, IF(G16>=0.7, 3.0, IF(G16>=0.65, 2.5, IF(G16>=0.6, 2.0, IF(G16>=0.55, 1.5, IF(G16>=0.5, 1.0, 0.0))))))))*C16, "") | M16: =IF(AND(ISNUMBER(F16), F16>0), F16*C16, "") | N16: =IF(AND(D16="Technical Core", ISNUMBER(F16), F16>0), F16*C16, "") | O16: =IF(AND(D16="Technical Core", ISNUMBER(F16), F16>0), C16, "")
A17: =HYPERLINK("#'WTP100'!A1", "WTP100") | B17: Work Term Preparation | C17: 1 | D17: Co-op Prep | E17: ='WTP100'!A6 | F17: =IF('WTP100'!A6>0, 'WTP100'!E6, "") | G17: =IF('WTP100'!A6>0, 'WTP100'!G6, "") | H17: =IF('WTP100'!A6>0, IF('WTP100'!E6>=0.8, "SAT", "UN"), "--") | I17: "" | J17: ='WTP100'!I6 | K17: =IF(ISNUMBER(I17), I17*C17, "") | L17: =IF(ISNUMBER(G17), IF(G17>=0.9, 4.0, IF(G17>=0.8, 4.0, IF(G17>=0.75, 3.5, IF(G17>=0.7, 3.0, IF(G17>=0.65, 2.5, IF(G17>=0.6, 2.0, IF(G17>=0.55, 1.5, IF(G17>=0.5, 1.0, 0.0))))))))*C17, "") | M17: =IF(AND(ISNUMBER(F17), F17>0), F17*C17, "") | N17: =IF(AND(D17="Technical Core", ISNUMBER(F17), F17>0), F17*C17, "") | O17: =IF(AND(D17="Technical Core", ISNUMBER(F17), F17>0), C17, "")
A18: SEMESTER 3 WEIGHTED TOTALS | C18: =SUM(C11:C17) | D18: -- | E18: =AVERAGE(E11:E17) | F18: =E6 | G18: =C6 | H18: =IF(ISNUMBER(G6), IF(G6>=0.9, "A+", IF(G6>=0.8, "A", IF(G6>=0.75, "B+", IF(G6>=0.7, "B", IF(G6>=0.65, "C+", IF(G6>=0.6, "C", IF(G6>=0.55, "D+", IF(G6>=0.5, "D", "F")))))))), "--") | I18: =A6 | J18: =IF(COUNTIF(J11:J17, "*WARNING*")>0, "⚠️ ACTION REQUIRED", "ALL CLEAR")
A21: OFFICIAL SENECA POLYTECHNIC GRADING SCALE (4.0 SCALE) | G21: SEMESTER 3 ACADEMIC POLICY & HURDLE SUMMARY
A22: A+ | B22: 90% - 100% | C22: 4 | D22: Exemplary Performance | G22: 1. Dual-Criterion Hurdle: CSN305, DAT330, MST300 & SEC320 require a weighted average of >=50% on all tests/exams combined to obtain course credit.
A23: A | B23: 80% - 89% | C23: 4 | D23: Excellent Comprehension
A24: B+ | B24: 75% - 79% | C24: 3.5 | D24: Very Good Standing | G24: 2. Lab Completion Hurdle: All lab exercises must be satisfactorily submitted and verified for technical course passing.
A25: B | B25: 70% - 74% | C25: 3 | D25: Good Standing
A26: C+ | B26: 65% - 69% | C26: 2.5 | D26: Satisfactory Achievement | G26: 3. Technical Core Isolation: 5 core computing courses (CSN305, DAT330, MST300, SEC320, OPS345) are tracked separately from General Electives.
A27: C | B27: 60% - 64% | C27: 2 | D27: Minimum Technical Prerequisite
A28: D+ | B28: 55% - 59% | C28: 1.5 | D28: Marginal Pass | G28: 4. Non-GPA Co-op Course: WTP100 is graded on a Satisfactory/Unsatisfactory (SAT/UN) basis. All 14 Knowledge Checks must achieve >=80%.
A29: D | B29: 50% - 54% | C29: 1 | D29: Minimum Course Pass
A30: F | B30: 0% - 49% | C30: 0 | D30: Unsatisfactory / Course Failure

Sheet CSN305
A1: CSN305: Virtualization and Cloud Infrastructure | I1: =HYPERLINK("#'Dashboard & GPA'!A1", "⬅ Back to Dashboard")
A2: Credits: 3.0 • Classification: Technical Computing Core • Grade Scale: Seneca 4.0
A3: 📌 PASSING REQUIREMENTS: Achieve a grade of 50% or higher in the overall course • Achieve a weighted average of 50% or higher on all tests • Satisfactorily complete all labs
A5: COMPLETED WEIGHT | C5: WEIGHTED EARNED | E5: CURRENT AVERAGE | G5: PROJECTED FINAL | I5: HURDLE COMPLIANCE
A6: =SUMIF(E11:E24, "<>", C11:C24) | C6: =SUM(G11:G24) | E6: =IF(A6>0, C6/A6, "--") | G6: =IF(A6>0, C6 + (1-A6)*E6, "--") | I6: =IF(SUMIF(E21:E24, "<>", C21:C24)<=0, "PENDING", IF(SUM(G21:G24)/SUMIF(E21:E24, "<>", C21:C24)>=0.5, "ON TRACK (PASSED)", "⚠️ WARNING: <50%"))
A7: of 100.0% Course Total | C7: Points Accumulated | E7: Based on graded work | G7: Assuming current pace | I7: Must score >=50% on Tests
A9: 💡 ENTER MARKS: Enter your points earned in the light blue 'Earned Pts' column (Col E). Scores, weighted points, and GPA recalculate automatically.
A10: Category | B10: Assessment Deliverable | C10: Weight % | D10: Max Pts | E10: Earned Pts ✍️ | F10: Score % | G10: Weighted Earned % | H10: Due Date | I10: Status | J10: Hurdle / Notes
A11: Labs | B11: Lab 1 | C11: 0.04 | D11: 100 | F11: =IF(OR(ISBLANK(E11), E11=""), "", E11/D11) | G11: =IF(OR(ISBLANK(E11), E11=""), "", F11*C11) | H11: 2026-09-17 | I11: Not Started
A12: Labs | B12: Lab 2 | C12: 0.04 | D12: 100 | F12: =IF(OR(ISBLANK(E12), E12=""), "", E12/D12) | G12: =IF(OR(ISBLANK(E12), E12=""), "", F12*C12) | H12: 2026-09-24 | I12: Not Started
A13: Labs | B13: Lab 3 | C13: 0.04 | D13: 100 | F13: =IF(OR(ISBLANK(E13), E13=""), "", E13/D13) | G13: =IF(OR(ISBLANK(E13), E13=""), "", F13*C13) | H13: 2026-10-01 | I13: Not Started
A14: Labs | B14: Lab 4 | C14: 0.04 | D14: 100 | F14: =IF(OR(ISBLANK(E14), E14=""), "", E14/D14) | G14: =IF(OR(ISBLANK(E14), E14=""), "", F14*C14) | H14: 2026-10-08 | I14: Not Started
A15: Labs | B15: Lab 5 | C15: 0.04 | D15: 100 | F15: =IF(OR(ISBLANK(E15), E15=""), "", E15/D15) | G15: =IF(OR(ISBLANK(E15), E15=""), "", F15*C15) | H15: 2026-10-15 | I15: Not Started
A16: Labs | B16: Lab 6 | C16: 0.04 | D16: 100 | F16: =IF(OR(ISBLANK(E16), E16=""), "", E16/D16) | G16: =IF(OR(ISBLANK(E16), E16=""), "", F16*C16) | H16: 2026-10-22 | I16: Not Started
A17: Labs | B17: Lab 7 | C17: 0.04 | D17: 100 | F17: =IF(OR(ISBLANK(E17), E17=""), "", E17/D17) | G17: =IF(OR(ISBLANK(E17), E17=""), "", F17*C17) | H17: 2026-11-12 | I17: Not Started
A18: Labs | B18: Lab 8 | C18: 0.04 | D18: 100 | F18: =IF(OR(ISBLANK(E18), E18=""), "", E18/D18) | G18: =IF(OR(ISBLANK(E18), E18=""), "", F18*C18) | H18: 2026-11-19 | I18: Not Started
A19: Labs | B19: Lab 9 | C19: 0.04 | D19: 100 | F19: =IF(OR(ISBLANK(E19), E19=""), "", E19/D19) | G19: =IF(OR(ISBLANK(E19), E19=""), "", F19*C19) | H19: 2026-12-3 | I19: Not Started
A20: Labs | B20: Lab 10 | C20: 0.04 | D20: 100 | F20: =IF(OR(ISBLANK(E20), E20=""), "", E20/D20) | G20: =IF(OR(ISBLANK(E20), E20=""), "", F20*C20) | H20: 2026-09-17 | I20: Not Started
A21: Tests | B21: Test 1 | C21: 0.15 | D21: 100 | F21: =IF(OR(ISBLANK(E21), E21=""), "", E21/D21) | G21: =IF(OR(ISBLANK(E21), E21=""), "", F21*C21) | H21: 2026-10-01 | I21: Not Started | J21: Mandatory Test Hurdle (>=50%)
A22: Tests | B22: Test 2 | C22: 0.15 | D22: 100 | F22: =IF(OR(ISBLANK(E22), E22=""), "", E22/D22) | G22: =IF(OR(ISBLANK(E22), E22=""), "", F22*C22) | H22: 2026-10-22 | I22: Not Started | J22: Mandatory Test Hurdle (>=50%)
A23: Tests | B23: Test 3 | C23: 0.15 | D23: 100 | F23: =IF(OR(ISBLANK(E23), E23=""), "", E23/D23) | G23: =IF(OR(ISBLANK(E23), E23=""), "", F23*C23) | H23: 2026-11-19 | I23: Not Started | J23: Mandatory Test Hurdle (>=50%)
A24: Tests | B24: Test 4 | C24: 0.15 | D24: 100 | F24: =IF(OR(ISBLANK(E24), E24=""), "", E24/D24) | G24: =IF(OR(ISBLANK(E24), E24=""), "", F24*C24) | H24: 2026-12-10 | I24: Not Started | J24: Mandatory Test Hurdle (>=50%)
A25: COURSE TOTAL & WEIGHTS | C25: =SUM(C11:C24) | D25: =SUM(D11:D24) | E25: =SUM(E11:E24) | F25: -- | G25: =SUM(G11:G24)

Sheet DAT330
A1: DAT330: Introduction to Databases | I1: =HYPERLINK("#'Dashboard & GPA'!A1", "⬅ Back to Dashboard")
A2: Credits: 3.0 • Classification: Technical Computing Core • Grade Scale: Seneca 4.0
A3: 📌 PASSING REQUIREMENTS: Achieve a grade of 50% or higher in the overall course • Achieve a weighted average of 50% or higher on all labs • Achieve a weighted average of 50% or higher on all tests • Achieve a weighted average of 50% or higher on assignments and project
A5: COMPLETED WEIGHT | C5: WEIGHTED EARNED | E5: CURRENT AVERAGE | G5: PROJECTED FINAL | I5: HURDLE COMPLIANCE
A6: =SUMIF(E11:E30, "<>", C11:C30) | C6: =SUM(G11:G30) | E6: =IF(A6>0, C6/A6, "--") | G6: =IF(A6>0, C6 + (1-A6)*E6, "--") | I6: =IF(SUMIF(E28:E30, "<>", C28:C30)<=0, "PENDING", IF(SUM(G28:G30)/SUMIF(E28:E30, "<>", C28:C30)>=0.5, "ON TRACK (PASSED)", "⚠️ WARNING: <50%"))
A7: of 100.0% Course Total | C7: Points Accumulated | E7: Based on graded work | G7: Assuming current pace | I7: Must score >=50% on Tests
A9: 💡 ENTER MARKS: Enter your points earned in the light blue 'Earned Pts' column (Col E). Scores, weighted points, and GPA recalculate automatically.
A10: Category | B10: Assessment Deliverable | C10: Weight % | D10: Max Pts | E10: Earned Pts ✍️ | F10: Score % | G10: Weighted Earned % | H10: Due Date | I10: Status | J10: Hurdle / Notes
A11: Management of Budget Allotment | B11: Budget Allotment | C11: 0.1 | D11: 100 | F11: =IF(OR(ISBLANK(E11), E11=""), "", E11/D11) | G11: =IF(OR(ISBLANK(E11), E11=""), "", F11*C11) | H11: TBA | I11: Not Started
A12: Labs | B12: Lab 1 | C12: 0.025 | D12: 100 | F12: =IF(OR(ISBLANK(E12), E12=""), "", E12/D12) | G12: =IF(OR(ISBLANK(E12), E12=""), "", F12*C12) | H12: 2026-09-17 | I12: Done
A13: Labs | B13: Lab 2 | C13: 0.025 | D13: 100 | F13: =IF(OR(ISBLANK(E13), E13=""), "", E13/D13) | G13: =IF(OR(ISBLANK(E13), E13=""), "", F13*C13) | H13: 2026-09-24 | I13: Not Started
A14: Labs | B14: Lab 3 | C14: 0.025 | D14: 100 | F14: =IF(OR(ISBLANK(E14), E14=""), "", E14/D14) | G14: =IF(OR(ISBLANK(E14), E14=""), "", F14*C14) | H14: 2026-10-08 | I14: Not Started
A15: Labs | B15: Lab 4 | C15: 0.025 | D15: 100 | F15: =IF(OR(ISBLANK(E15), E15=""), "", E15/D15) | G15: =IF(OR(ISBLANK(E15), E15=""), "", F15*C15) | H15: 2026-10-15 | I15: Not Started
A16: Labs | B16: Lab 5 | C16: 0.025 | D16: 100 | F16: =IF(OR(ISBLANK(E16), E16=""), "", E16/D16) | G16: =IF(OR(ISBLANK(E16), E16=""), "", F16*C16) | H16: 2026-11-5 | I16: Not Started
A17: Labs | B17: Lab 6 | C17: 0.025 | D17: 100 | F17: =IF(OR(ISBLANK(E17), E17=""), "", E17/D17) | G17: =IF(OR(ISBLANK(E17), E17=""), "", F17*C17) | H17: 2026-11-12 | I17: Not Started
A18: Labs | B18: Lab 7 | C18: 0.025 | D18: 100 | F18: =IF(OR(ISBLANK(E18), E18=""), "", E18/D18) | G18: =IF(OR(ISBLANK(E18), E18=""), "", F18*C18) | H18: 2026-11-19 | I18: Not Started
A19: Labs | B19: Lab 8 | C19: 0.025 | D19: 100 | F19: =IF(OR(ISBLANK(E19), E19=""), "", E19/D19) | G19: =IF(OR(ISBLANK(E19), E19=""), "", F19*C19) | H19: 2026-12-3 | I19: Not Started
A20: Quizzes | B20: Quiz 1 | C20: 0.02 | D20: 100 | F20: =IF(OR(ISBLANK(E20), E20=""), "", E20/D20) | G20: =IF(OR(ISBLANK(E20), E20=""), "", F20*C20) | H20: 2026-09-21 | I20: Not Started
A21: Quizzes | B21: Quiz 2 | C21: 0.02 | D21: 100 | F21: =IF(OR(ISBLANK(E21), E21=""), "", E21/D21) | G21: =IF(OR(ISBLANK(E21), E21=""), "", F21*C21) | H21: 2026-09-28 | I21: Not Started
A22: Quizzes | B22: Quiz 3 | C22: 0.02 | D22: 100 | F22: =IF(OR(ISBLANK(E22), E22=""), "", E22/D22) | G22: =IF(OR(ISBLANK(E22), E22=""), "", F22*C22) | H22: 2026-11-09 | I22: Not Started
... A27: Assignments | B27: Assignment 3 | C27: 0.05 | D27: 100 | F27: =IF(OR(ISBLANK(E27), E27=""), "", E27/D27) | G27: =IF(OR(ISBLANK(E27), E27=""), "", F27*C27) | H27: 2026-11-26 | I27: Not Started
A28: Midterm Test | B28: Midterm Test | C28: 0.15 | D28: 100 | F28: =IF(OR(ISBLANK(E28), E28=""), "", E28/D28) | G28: =IF(OR(ISBLANK(E28), E28=""), "", F28*C28) | H28: 2026-10-19 | I28: Not Started | J28: Mandatory Test Hurdle (>=50%)
A29: Final Test | B29: Final Test | C29: 0.15 | D29: 100 | F29: =IF(OR(ISBLANK(E29), E29=""), "", E29/D29) | G29: =IF(OR(ISBLANK(E29), E29=""), "", F29*C29) | H29: TBA | I29: Not Started | J29: Mandatory Test Hurdle (>=50%)
A30: Final Project | B30: Final Project | C30: 0.15 | D30: 100 | F30: =IF(OR(ISBLANK(E30), E30=""), "", E30/D30) | G30: =IF(OR(ISBLANK(E30), E30=""), "", F30*C30) | H30: 2026-12-07 | I30: Not Started | J30: Mandatory Test Hurdle (>=50%)
A31: COURSE TOTAL & WEIGHTS | C31: =SUM(C11:C30) | D31: =SUM(D11:D30) | E31: =SUM(E11:E30) | F31: -- | G31: =SUM(G11:G30)

Sheet MST300
A1: MST300: Introduction to Microsoft Cloud Technologies | I1: =HYPERLINK("#'Dashboard & GPA'!A1", "⬅ Back to Dashboard")
A2: Credits: 3.0 • Classification: Technical Computing Core • Grade Scale: Seneca 4.0
A3: 📌 PASSING REQUIREMENTS: Achieve a grade of 50% or higher in the overall course • Achieve a weighted average of 50% or higher on all labs • Achieve a weighted average of 50% or higher on all projects
A5: COMPLETED WEIGHT | C5: WEIGHTED EARNED | E5: CURRENT AVERAGE | G5: PROJECTED FINAL | I5: HURDLE COMPLIANCE
A6: =SUMIF(E11:E27, "<>", C11:C27) | C6: =SUM(G11:G27) | E6: =IF(A6>0, C6/A6, "--") | G6: =IF(A6>0, C6 + (1-A6)*E6, "--") | I6: =IF(SUMIF(E26:E27, "<>", C26:C27)<=0, "PENDING", IF(SUM(G26:G27)/SUMIF(E26:E27, "<>", C26:C27)>=0.5, "ON TRACK (PASSED)", "⚠️ WARNING: <50%"))
A7: of 100.0% Course Total | C7: Points Accumulated | E7: Based on graded work | G7: Assuming current pace | I7: Must score >=50% on Tests
A9: 💡 ENTER MARKS: Enter your points earned in the light blue 'Earned Pts' column (Col E). Scores, weighted points, and GPA recalculate automatically.
A10: Category | B10: Assessment Deliverable | C10: Weight % | D10: Max Pts | E10: Earned Pts ✍️ | F10: Score % | G10: Weighted Earned % | H10: Due Date | I10: Status | J10: Hurdle / Notes
A11: Management of Budget Allotment | B11: Budget Allotment | C11: 0.1 | D11: 100 | F11: =IF(OR(ISBLANK(E11), E11=""), "", E11/D11) | G11: =IF(OR(ISBLANK(E11), E11=""), "", F11*C11) | H11: TBA | I11: Not Started
A12: Labs | B12: Lab 1 | C12: 0.0333 | D12: 100 | F12: =IF(OR(ISBLANK(E12), E12=""), "", E12/D12) | G12: =IF(OR(ISBLANK(E12), E12=""), "", F12*C12) | H12: 2026-10-13 | I12: Not Started
A13: Labs | B13: Lab 2 | C13: 0.0333 | D13: 100 | F13: =IF(OR(ISBLANK(E13), E13=""), "", E13/D13) | G13: =IF(OR(ISBLANK(E13), E13=""), "", F13*C13) | H13: 2026-10-6 | I13: Not Started
A14: Labs | B14: Lab 3 | C14: 0.0333 | D14: 100 | F14: =IF(OR(ISBLANK(E14), E14=""), "", E14/D14) | G14: =IF(OR(ISBLANK(E14), E14=""), "", F14*C14) | H14: 2026-10-6 | I14: Not Started
A15: Labs | B15: Lab 4 | C15: 0.0333 | D15: 100 | F15: =IF(OR(ISBLANK(E15), E15=""), "", E15/D15) | G15: =IF(OR(ISBLANK(E15), E15=""), "", F15*C15) | H15: 2026-10-6 | I15: Not Started
A16: Labs | B16: Lab 5 | C16: 0.0333 | D16: 100 | F16: =IF(OR(ISBLANK(E16), E16=""), "", E16/D16) | G16: =IF(OR(ISBLANK(E16), E16=""), "", F16*C16) | H16: 2026-10-6 | I16: Not Started
A17: Labs | B17: Lab 6 | C17: 0.0335 | D17: 100 | F17: =IF(OR(ISBLANK(E17), E17=""), "", E17/D17) | G17: =IF(OR(ISBLANK(E17), E17=""), "", F17*C17) | H17: 2026-10-6 | I17: Not Started
A18: Quizzes | B18: Quiz 1 | C18: 0.025 | D18: 100 | F18: =IF(OR(ISBLANK(E18), E18=""), "", E18/D18) | G18: =IF(OR(ISBLANK(E18), E18=""), "", F18*C18) | H18: 2026-9-22 | I18: Not Started
A19: Quizzes | B19: Quiz 2 | C19: 0.025 | D19: 100 | F19: =IF(OR(ISBLANK(E19), E19=""), "", E19/D19) | G19: =IF(OR(ISBLANK(E19), E19=""), "", F19*C19) | H19: 2026-10-06 | I19: Not Started
A20: Quizzes | B20: Quiz 3 | C20: 0.025 | D20: 100 | F20: =IF(OR(ISBLANK(E20), E20=""), "", E20/D20) | G20: =IF(OR(ISBLANK(E20), E20=""), "", F20*C20) | H20: 2026-10-13 | I20: Not Started
A21: Quizzes | B21: Quiz 4 | C21: 0.025 | D21: 100 | F21: =IF(OR(ISBLANK(E21), E21=""), "", E21/D21) | G21: =IF(OR(ISBLANK(E21), E21=""), "", F21*C21) | H21: 2026-11-10 | I21: Not Started
A22: Quizzes | B22: Quiz 5 | C22: 0.025 | D22: 100 | F22: =IF(OR(ISBLANK(E22), E22=""), "", E22/D22) | G22: =IF(OR(ISBLANK(E22), E22=""), "", F22*C22) | H22: 2026-12-01 | I22: Not Started
... A25: Projects | B25: Project 2 | C25: 0.15 | D25: 100 | F25: =IF(OR(ISBLANK(E25), E25=""), "", E25/D25) | G25: =IF(OR(ISBLANK(E25), E25=""), "", F25*C25) | H25: 2026-12-08 | I25: Not Started
A26: Tests | B26: Midterm Test | C26: 0.1 | D26: 100 | F26: =IF(OR(ISBLANK(E26), E26=""), "", E26/D26) | G26: =IF(OR(ISBLANK(E26), E26=""), "", F26*C26) | H26: TBA | I26: Not Started | J26: Mandatory Test Hurdle (>=50%)
A27: Tests | B27: Final Test | C27: 0.15 | D27: 100 | F27: =IF(OR(ISBLANK(E27), E27=""), "", E27/D27) | G27: =IF(OR(ISBLANK(E27), E27=""), "", F27*C27) | H27: TBA | I27: Not Started | J27: Mandatory Test Hurdle (>=50%)
A28: COURSE TOTAL & WEIGHTS | C28: =SUM(C11:C27) | D28: =SUM(D11:D27) | E28: =SUM(E11:E27) | F28: -- | G28: =SUM(G11:G27)

Sheet PSY262
A1: PSY262: Applied Psychology of Mindfulness | I1: =HYPERLINK("#'Dashboard & GPA'!A1", "⬅ Back to Dashboard")
A2: Credits: 3.0 • Classification: General Elective • Grade Scale: Seneca 4.0
A3: 📌 PASSING REQUIREMENTS: Achieve a grade of 50% or higher in the overall course
A5: COMPLETED WEIGHT | C5: WEIGHTED EARNED | E5: CURRENT AVERAGE | G5: PROJECTED FINAL | I5: HURDLE COMPLIANCE
A6: =SUMIF(E11:E24, "<>", C11:C24) | C6: =SUM(G11:G24) | E6: =IF(A6>0, C6/A6, "--") | G6: =IF(A6>0, C6 + (1-A6)*E6, "--") | I6: =IF(SUMIF(E24:E24, "<>", C24:C24)<=0, "PENDING", IF(SUM(G24:G24)/SUMIF(E24:E24, "<>", C24:C24)>=0.5, "ON TRACK (PASSED)", "⚠️ WARNING: <50%"))
A7: of 100.0% Course Total | C7: Points Accumulated | E7: Based on graded work | G7: Assuming current pace | I7: Must score >=50% on Tests
A9: 💡 ENTER MARKS: Enter your points earned in the light blue 'Earned Pts' column (Col E). Scores, weighted points, and GPA recalculate automatically.
A10: Category | B10: Assessment Deliverable | C10: Weight % | D10: Max Pts | E10: Earned Pts ✍️ | F10: Score % | G10: Weighted Earned % | H10: Due Date | I10: Status | J10: Hurdle / Notes
A11: In-Class Assignments | B11: Assignment 1 | C11: 0.025 | D11: 100 | F11: =IF(OR(ISBLANK(E11), E11=""), "", E11/D11) | G11: =IF(OR(ISBLANK(E11), E11=""), "", F11*C11) | H11: 2026-9-18 | I11: Not Started
A12: In-Class Assignments | B12: Assignment 2 | C12: 0.025 | D12: 100 | F12: =IF(OR(ISBLANK(E12), E12=""), "", E12/D12) | G12: =IF(OR(ISBLANK(E12), E12=""), "", F12*C12) | H12: 2026-9-18 | I12: Not Started
A13: In-Class Assignments | B13: Assignment 3 | C13: 0.025 | D13: 100 | F13: =IF(OR(ISBLANK(E13), E13=""), "", E13/D13) | G13: =IF(OR(ISBLANK(E13), E13=""), "", F13*C13) | H13: 2026-9-25 | I13: Not Started
A14: In-Class Assignments | B14: Assignment 4 | C14: 0.025 | D14: 100 | F14: =IF(OR(ISBLANK(E14), E14=""), "", E14/D14) | G14: =IF(OR(ISBLANK(E14), E14=""), "", F14*C14) | H14: 2026-10-02 | I14: Not Started
A15: In-Class Assignments | B15: Assignment 5 | C15: 0.025 | D15: 100 | F15: =IF(OR(ISBLANK(E15), E15=""), "", E15/D15) | G15: =IF(OR(ISBLANK(E15), E15=""), "", F15*C15) | H15: 2026-10-09 | I15: Not Started
A16: In-Class Assignments | B16: Assignment 6 | C16: 0.025 | D16: 100 | F16: =IF(OR(ISBLANK(E16), E16=""), "", E16/D16) | G16: =IF(OR(ISBLANK(E16), E16=""), "", F16*C16) | H16: 2026-10-09 | I16: Not Started
A17: In-Class Assignments | B17: Assignment 7 | C17: 0.025 | D17: 100 | F17: =IF(OR(ISBLANK(E17), E17=""), "", E17/D17) | G17: =IF(OR(ISBLANK(E17), E17=""), "", F17*C17) | H17: 2026-10-16 | I17: Not Started
A18: In-Class Assignments | B18: Assignment 8 | C18: 0.025 | D18: 100 | F18: =IF(OR(ISBLANK(E18), E18=""), "", E18/D18) | G18: =IF(OR(ISBLANK(E18), E18=""), "", F18*C18) | H18: 2026-10-23 | I18: Not Started
A19: In-Class Assignments | B19: Assignment 9 | C19: 0.025 | D19: 100 | F19: =IF(OR(ISBLANK(E19), E19=""), "", E19/D19) | G19: =IF(OR(ISBLANK(E19), E19=""), "", F19*C19) | H19: 2026-10-23 | I19: Not Started
A20: In-Class Assignments | B20: Assignment 10 | C20: 0.025 | D20: 100 | F20: =IF(OR(ISBLANK(E20), E20=""), "", E20/D20) | G20: =IF(OR(ISBLANK(E20), E20=""), "", F20*C20) | H20: 2026-9-18 | I20: Not Started
A21: Writing Assignment | B21: Writing Assignment | C21: 0.1 | D21: 100 | F21: =IF(OR(ISBLANK(E21), E21=""), "", E21/D21) | G21: =IF(OR(ISBLANK(E21), E21=""), "", F21*C21) | H21: TBA | I21: Not Started
A22: Quiz 1 | B22: Quiz 1 | C22: 0.2 | D22: 100 | F22: =IF(OR(ISBLANK(E22), E22=""), "", E22/D22) | G22: =IF(OR(ISBLANK(E22), E22=""), "", F22*C22) | H22: 2026-10-02 | I22: Not Started
A23: Quiz 2 | B23: Quiz 2 | C23: 0.2 | D23: 100 | F23: =IF(OR(ISBLANK(E23), E23=""), "", E23/D23) | G23: =IF(OR(ISBLANK(E23), E23=""), "", F23*C23) | H23: 2026-11-06 | I23: Not Started
A24: Final Exam | B24: Final Exam | C24: 0.25 | D24: 100 | F24: =IF(OR(ISBLANK(E24), E24=""), "", E24/D24) | G24: =IF(OR(ISBLANK(E24), E24=""), "", F24*C24) | H24: 2026-12-11 | I24: Not Started | J24: Mandatory Test Hurdle (>=50%)
A25: COURSE TOTAL & WEIGHTS | C25: =SUM(C11:C24) | D25: =SUM(D11:D24) | E25: =SUM(E11:E24) | F25: -- | G25: =SUM(G11:G24)

Sheet SEC320
A1: SEC320: Incident Response and Computer Forensics | I1: =HYPERLINK("#'Dashboard & GPA'!A1", "⬅ Back to Dashboard")
A2: Credits: 3.0 • Classification: Technical Computing Core • Grade Scale: Seneca 4.0
A3: 📌 PASSING REQUIREMENTS: Achieve a grade of 50% or higher in the overall course • Achieve a weighted average of 50% or higher on all tests • Achieve a weighted average of 50% or higher on all labs • Satisfactorily complete all labs and assignments
A5: COMPLETED WEIGHT | C5: WEIGHTED EARNED | E5: CURRENT AVERAGE | G5: PROJECTED FINAL | I5: HURDLE COMPLIANCE
A6: =SUMIF(E11:E25, "<>", C11:C25) | C6: =SUM(G11:G25) | E6: =IF(A6>0, C6/A6, "--") | G6: =IF(A6>0, C6 + (1-A6)*E6, "--") | I6: =IF(SUMIF(E11:E25, "<>", C11:C25)<=0, "PENDING", IF(SUM(G11:G25)/SUMIF(E11:E25, "<>", C11:C25)>=0.5, "ON TRACK (PASSED)", "⚠️ WARNING: <50%"))
A7: of 100.0% Course Total | C7: Points Accumulated | E7: Based on graded work | G7: Assuming current pace | I7: Must score >=50% on Tests
A9: 💡 ENTER MARKS: Enter your points earned in the light blue 'Earned Pts' column (Col E). Scores, weighted points, and GPA recalculate automatically.
A10: Category | B10: Assessment Deliverable | C10: Weight % | D10: Max Pts | E10: Earned Pts ✍️ | F10: Score % | G10: Weighted Earned % | H10: Due Date | I10: Status | J10: Hurdle / Notes
A11: Practical Tests | B11: Practical Test 1 | C11: 0.15 | D11: 100 | F11: =IF(OR(ISBLANK(E11), E11=""), "", E11/D11) | G11: =IF(OR(ISBLANK(E11), E11=""), "", F11*C11) | H11: TBA | I11: Not Started | J11: Mandatory Test Hurdle (>=50%)
A12: Practical Tests | B12: Practical Test 2 | C12: 0.15 | D12: 100 | F12: =IF(OR(ISBLANK(E12), E12=""), "", E12/D12) | G12: =IF(OR(ISBLANK(E12), E12=""), "", F12*C12) | H12: TBA | I12: Not Started | J12: Mandatory Test Hurdle (>=50%)
A13: Labs | B13: Lab 1 | C13: 0.04 | D13: 100 | F13: =IF(OR(ISBLANK(E13), E13=""), "", E13/D13) | G13: =IF(OR(ISBLANK(E13), E13=""), "", F13*C13) | H13: 2026-9-18 | I13: Not Started
A14: Labs | B14: Lab 2 | C14: 0.04 | D14: 100 | F14: =IF(OR(ISBLANK(E14), E14=""), "", E14/D14) | G14: =IF(OR(ISBLANK(E14), E14=""), "", F14*C14) | H14: 2026-9-25 | I14: Not Started
A15: Labs | B15: Lab 3 | C15: 0.04 | D15: 100 | F15: =IF(OR(ISBLANK(E15), E15=""), "", E15/D15) | G15: =IF(OR(ISBLANK(E15), E15=""), "", F15*C15) | H15: 2026-10-2 | I15: Not Started
A16: Labs | B16: Lab 4 | C16: 0.04 | D16: 100 | F16: =IF(OR(ISBLANK(E16), E16=""), "", E16/D16) | G16: =IF(OR(ISBLANK(E16), E16=""), "", F16*C16) | H16: 2026-10-09 | I16: Not Started
A17: Labs | B17: Lab 5 | C17: 0.04 | D17: 100 | F17: =IF(OR(ISBLANK(E17), E17=""), "", E17/D17) | G17: =IF(OR(ISBLANK(E17), E17=""), "", F17*C17) | H17: 2026-10-16 | I17: Not Started
A18: Labs | B18: Lab 6 | C18: 0.04 | D18: 100 | F18: =IF(OR(ISBLANK(E18), E18=""), "", E18/D18) | G18: =IF(OR(ISBLANK(E18), E18=""), "", F18*C18) | H18: 2026-11-06 | I18: Not Started
A19: Labs | B19: Lab 7 | C19: 0.04 | D19: 100 | F19: =IF(OR(ISBLANK(E19), E19=""), "", E19/D19) | G19: =IF(OR(ISBLANK(E19), E19=""), "", F19*C19) | H19: 2026-11-13 | I19: Not Started
A20: Labs | B20: Lab 8 | C20: 0.04 | D20: 100 | F20: =IF(OR(ISBLANK(E20), E20=""), "", E20/D20) | G20: =IF(OR(ISBLANK(E20), E20=""), "", F20*C20) | H20: 2026-11-20 | I20: Not Started
A21: Labs | B21: Lab 9 | C21: 0.04 | D21: 100 | F21: =IF(OR(ISBLANK(E21), E21=""), "", E21/D21) | G21: =IF(OR(ISBLANK(E21), E21=""), "", F21*C21) | H21: 2026-11-27 | I21: Not Started
A22: Labs | B22: Lab 10 | C22: 0.04 | D22: 100 | F22: =IF(OR(ISBLANK(E22), E22=""), "", E22/D22) | G22: =IF(OR(ISBLANK(E22), E22=""), "", F22*C22) | H22: 2026-9-18 | I22: Not Started
A23: Final Project | B23: Project Proposal | C23: 0.05 | D23: 100 | F23: =IF(OR(ISBLANK(E23), E23=""), "", E23/D23) | G23: =IF(OR(ISBLANK(E23), E23=""), "", F23*C23) | H23: 2026-10-23 | I23: Not Started | J23: Mandatory Test Hurdle (>=50%)
A24: Final Project | B24: Project Presentation | C24: 0.1 | D24: 100 | F24: =IF(OR(ISBLANK(E24), E24=""), "", E24/D24) | G24: =IF(OR(ISBLANK(E24), E24=""), "", F24*C24) | H24: 2026-11-30 | I24: Not Started | J24: Mandatory Test Hurdle (>=50%)
A25: Final Project | B25: Final Report | C25: 0.15 | D25: 100 | F25: =IF(OR(ISBLANK(E25), E25=""), "", E25/D25) | G25: =IF(OR(ISBLANK(E25), E25=""), "", F25*C25) | H25: TBA | I25: Not Started | J25: Mandatory Test Hurdle (>=50%)
A26: COURSE TOTAL & WEIGHTS | C26: =SUM(C11:C25) | D26: =SUM(D11:D25) | E26: =SUM(E11:E25) | F26: -- | G26: =SUM(G11:G25)

Sheet OPS345
A1: OPS345: Open System Application Server | I1: =HYPERLINK("#'Dashboard & GPA'!A1", "⬅ Back to Dashboard")
A2: Credits: 3.0 • Classification: Technical Computing Core • Grade Scale: Seneca 4.0
A3: 📌 PASSING REQUIREMENTS: Achieve a grade of 50% or higher in the overall course
A5: COMPLETED WEIGHT | C5: WEIGHTED EARNED | E5: CURRENT AVERAGE | G5: PROJECTED FINAL | I5: HURDLE COMPLIANCE
A6: =SUMIF(E11:E26, "<>", C11:C26) | C6: =SUM(G11:G26) | E6: =IF(A6>0, C6/A6, "--") | G6: =IF(A6>0, C6 + (1-A6)*E6, "--") | I6: =IF(SUMIF(E25:E26, "<>", C25:C26)<=0, "PENDING", IF(SUM(G25:G26)/SUMIF(E25:E26, "<>", C25:C26)>=0.5, "ON TRACK (PASSED)", "⚠️ WARNING: <50%"))
A7: of 100.0% Course Total | C7: Points Accumulated | E7: Based on graded work | G7: Assuming current pace | I7: Must score >=50% on Tests
A9: 💡 ENTER MARKS: Enter your points earned in the light blue 'Earned Pts' column (Col E). Scores, weighted points, and GPA recalculate automatically.
A10: Category | B10: Assessment Deliverable | C10: Weight % | D10: Max Pts | E10: Earned Pts ✍️ | F10: Score % | G10: Weighted Earned % | H10: Due Date | I10: Status | J10: Hurdle / Notes
A11: Labs | B11: Lab 1 | C11: 0.02 | D11: 100 | F11: =IF(OR(ISBLANK(E11), E11=""), "", E11/D11) | G11: =IF(OR(ISBLANK(E11), E11=""), "", F11*C11) | H11: 2026-10-23 | I11: Not Started
A12: Labs | B12: Lab 2 | C12: 0.02 | D12: 100 | F12: =IF(OR(ISBLANK(E12), E12=""), "", E12/D12) | G12: =IF(OR(ISBLANK(E12), E12=""), "", F12*C12) | H12: 2026-10-23 | I12: Not Started
A13: Labs | B13: Lab 3 | C13: 0.02 | D13: 100 | F13: =IF(OR(ISBLANK(E13), E13=""), "", E13/D13) | G13: =IF(OR(ISBLANK(E13), E13=""), "", F13*C13) | H13: 2026-10-23 | I13: Not Started
A14: Labs | B14: Lab 4 | C14: 0.02 | D14: 100 | F14: =IF(OR(ISBLANK(E14), E14=""), "", E14/D14) | G14: =IF(OR(ISBLANK(E14), E14=""), "", F14*C14) | H14: 2026-10-23 | I14: Not Started
A15: Labs | B15: Lab 5 | C15: 0.02 | D15: 100 | F15: =IF(OR(ISBLANK(E15), E15=""), "", E15/D15) | G15: =IF(OR(ISBLANK(E15), E15=""), "", F15*C15) | H15: TBA | I15: Not Started
A16: Labs | B16: Lab 6 | C16: 0.02 | D16: 100 | F16: =IF(OR(ISBLANK(E16), E16=""), "", E16/D16) | G16: =IF(OR(ISBLANK(E16), E16=""), "", F16*C16) | H16: TBA | I16: Not Started
A17: Labs | B17: Lab 7 | C17: 0.02 | D17: 100 | F17: =IF(OR(ISBLANK(E17), E17=""), "", E17/D17) | G17: =IF(OR(ISBLANK(E17), E17=""), "", F17*C17) | H17: TBA | I17: Not Started
A18: Labs | B18: Lab 8 | C18: 0.02 | D18: 100 | F18: =IF(OR(ISBLANK(E18), E18=""), "", E18/D18) | G18: =IF(OR(ISBLANK(E18), E18=""), "", F18*C18) | H18: TBA | I18: Not Started
A19: Assignments | B19: Assignment 1 | C19: 0.15 | D19: 100 | F19: =IF(OR(ISBLANK(E19), E19=""), "", E19/D19) | G19: =IF(OR(ISBLANK(E19), E19=""), "", F19*C19) | H19: TBA | I19: Not Started
A20: Assignments | B20: Assignment 2 | C20: 0.15 | D20: 100 | F20: =IF(OR(ISBLANK(E20), E20=""), "", E20/D20) | G20: =IF(OR(ISBLANK(E20), E20=""), "", F20*C20) | H20: TBA | I20: Not Started
A21: Quizzes | B21: Quiz 1 | C21: 0.01 | D21: 100 | F21: =IF(OR(ISBLANK(E21), E21=""), "", E21/D21) | G21: =IF(OR(ISBLANK(E21), E21=""), "", F21*C21) | H21: TBA | I21: Not Started
A22: Quizzes | B22: Quiz 2 | C22: 0.01 | D22: 100 | F22: =IF(OR(ISBLANK(E22), E22=""), "", E22/D22) | G22: =IF(OR(ISBLANK(E22), E22=""), "", F22*C22) | H22: TBA | I22: Not Started
... A24: Quizzes | B24: Quiz 4 | C24: 0.01 | D24: 100 | F24: =IF(OR(ISBLANK(E24), E24=""), "", E24/D24) | G24: =IF(OR(ISBLANK(E24), E24=""), "", F24*C24) | H24: TBA | I24: Not Started
A25: Midterm Test | B25: Midterm Test | C25: 0.25 | D25: 100 | F25: =IF(OR(ISBLANK(E25), E25=""), "", E25/D25) | G25: =IF(OR(ISBLANK(E25), E25=""), "", F25*C25) | H25: 2026-10-21 | I25: Not Started | J25: Mandatory Test Hurdle (>=50%)
A26: Final Test | B26: Final Test | C26: 0.25 | D26: 100 | F26: =IF(OR(ISBLANK(E26), E26=""), "", E26/D26) | G26: =IF(OR(ISBLANK(E26), E26=""), "", F26*C26) | H26: TBA | I26: Not Started | J26: Mandatory Test Hurdle (>=50%)
A27: COURSE TOTAL & WEIGHTS | C27: =SUM(C11:C26) | D27: =SUM(D11:D26) | E27: =SUM(E11:E26) | F27: -- | G27: =SUM(G11:G26)

Sheet WTP100
A1: WTP100: Work Term Preparation | I1: =HYPERLINK("#'Dashboard & GPA'!A1", "⬅ Back to Dashboard")
A2: Credits: 1.0 • Classification: Co-op Prep • Grade Scale: SAT/UN
A3: 📌 PASSING REQUIREMENTS: Successfully complete each of the 14 modules • Pass each Knowledge Check with a passing score of 80% or higher to earn SAT
A5: COMPLETED WEIGHT | C5: WEIGHTED EARNED | E5: CURRENT AVERAGE | G5: PROJECTED FINAL | I5: HURDLE COMPLIANCE
A6: =SUMIF(E11:E24, "<>", C11:C24) | C6: =SUM(G11:G24) | E6: =IF(A6>0, C6/A6, "--") | G6: =IF(A6>0, C6 + (1-A6)*E6, "--") | I6: =IF(A6>0, IF(E6>=0.5, "ON TRACK (PASSED)", "NEEDS ATTENTION"), "PENDING")
A7: of 100.0% Course Total | C7: Points Accumulated | E7: Based on graded work | G7: Assuming current pace | I7: Overall >=50% to Pass
A9: 💡 ENTER MARKS: Enter your points earned in the light blue 'Earned Pts' column (Col E). Scores, weighted points, and GPA recalculate automatically.
A10: Category | B10: Assessment Deliverable | C10: Weight % | D10: Max Pts | E10: Earned Pts ✍️ | F10: Score % | G10: Weighted Earned % | H10: Due Date | I10: Status | J10: Hurdle / Notes
A11: Modules & Knowledge Checks | B11: Module 1 | C11: 0.0714 | D11: 100 | F11: =IF(OR(ISBLANK(E11), E11=""), "", E11/D11) | G11: =IF(OR(ISBLANK(E11), E11=""), "", F11*C11) | H11: 2026-9-11 | I11: Done
A12: Modules & Knowledge Checks | B12: Module 2 | C12: 0.0714 | D12: 100 | F12: =IF(OR(ISBLANK(E12), E12=""), "", E12/D12) | G12: =IF(OR(ISBLANK(E12), E12=""), "", F12*C12) | H12: 2026-9-11 | I12: Done
A13: Modules & Knowledge Checks | B13: Module 3 | C13: 0.0714 | D13: 100 | F13: =IF(OR(ISBLANK(E13), E13=""), "", E13/D13) | G13: =IF(OR(ISBLANK(E13), E13=""), "", F13*C13) | H13: 2026-9-11 | I13: In Progress
A14: Modules & Knowledge Checks | B14: Module 4 | C14: 0.0714 | D14: 100 | F14: =IF(OR(ISBLANK(E14), E14=""), "", E14/D14) | G14: =IF(OR(ISBLANK(E14), E14=""), "", F14*C14) | H14: 2026-9-18 | I14: Not Started
A15: Modules & Knowledge Checks | B15: Module 5 | C15: 0.0714 | D15: 100 | F15: =IF(OR(ISBLANK(E15), E15=""), "", E15/D15) | G15: =IF(OR(ISBLANK(E15), E15=""), "", F15*C15) | H15: 2026-9-18 | I15: Not Started
A16: Modules & Knowledge Checks | B16: Module 6 | C16: 0.0714 | D16: 100 | F16: =IF(OR(ISBLANK(E16), E16=""), "", E16/D16) | G16: =IF(OR(ISBLANK(E16), E16=""), "", F16*C16) | H16: 2026-9-25 | I16: Not Started
A17: Modules & Knowledge Checks | B17: Module 7 | C17: 0.0714 | D17: 100 | F17: =IF(OR(ISBLANK(E17), E17=""), "", E17/D17) | G17: =IF(OR(ISBLANK(E17), E17=""), "", F17*C17) | H17: 2026-9-25 | I17: Not Started
A18: Modules & Knowledge Checks | B18: Module 8 | C18: 0.0714 | D18: 100 | F18: =IF(OR(ISBLANK(E18), E18=""), "", E18/D18) | G18: =IF(OR(ISBLANK(E18), E18=""), "", F18*C18) | H18: 2026-10-02 | I18: Not Started
A19: Modules & Knowledge Checks | B19: Module 9 | C19: 0.0714 | D19: 100 | F19: =IF(OR(ISBLANK(E19), E19=""), "", E19/D19) | G19: =IF(OR(ISBLANK(E19), E19=""), "", F19*C19) | H19: 2026-10-02 | I19: Not Started
A20: Modules & Knowledge Checks | B20: Module 10 | C20: 0.0714 | D20: 100 | F20: =IF(OR(ISBLANK(E20), E20=""), "", E20/D20) | G20: =IF(OR(ISBLANK(E20), E20=""), "", F20*C20) | H20: 2026-9-11 | I20: Done
A21: Modules & Knowledge Checks | B21: Module 11 | C21: 0.0714 | D21: 100 | F21: =IF(OR(ISBLANK(E21), E21=""), "", E21/D21) | G21: =IF(OR(ISBLANK(E21), E21=""), "", F21*C21) | H21: 2026-9-11 | I21: Done
A22: Modules & Knowledge Checks | B22: Module 12 | C22: 0.0714 | D22: 100 | F22: =IF(OR(ISBLANK(E22), E22=""), "", E22/D22) | G22: =IF(OR(ISBLANK(E22), E22=""), "", F22*C22) | H22: 2026-9-11 | I22: Done
... A24: Modules & Knowledge Checks | B24: Module 14 | C24: 0.0718 | D24: 100 | F24: =IF(OR(ISBLANK(E24), E24=""), "", E24/D24) | G24: =IF(OR(ISBLANK(E24), E24=""), "", F24*C24) | H24: 2026-9-11 | I24: Done
A25: COURSE TOTAL & WEIGHTS | C25: =SUM(C11:C24) | D25: =SUM(D11:D24) | E25: =SUM(E11:E24) | F25: -- | G25: =SUM(G11:G24)

Sheet What-If Simulator
A1: What-If Final Grade Simulator & Academic Target Solver | I1: =HYPERLINK("#'Dashboard & GPA'!A1", "⬅ Back to Dashboard")
A2: Simulate required scores on uncompleted assignments, midterms, and final exams to achieve desired target letter grades
A3: 💡 TARGET SOLVER: Change your Target Letter Grade in Column G (blue shaded cells) to see the exact average needed on remaining coursework.
A5: CURRENT GPA | C5: PROJECTED GPA | E5: TARGET ACHIEVABLE | G5: CHALLENGING COURSES | I5: CRITICAL WATCH
A6: ='Dashboard & GPA'!A6 | C6: ='Dashboard & GPA'!C6 | E6: =COUNTIF(K11:K16, "*Achievable*") | G6: =COUNTIF(K11:K16, "*Challenging*") | I6: =COUNTIF(K11:K16, "*Impossible*")
A7: Based on completed work | C7: At current performance pace | E7: Courses within reach | G7: Requires >=85% on remainder | I7: Statistically Out of Reach
A10: Course Code | B10: Course Title | C10: Credits | D10: Completed % | E10: Earned Weight % | F10: Current Avg % | G10: Target Grade ✍️ | H10: Target % | I10: Remaining Weight % | J10: Required % on Remainder | K10: Feasibility Assessment
A11: =HYPERLINK("#'CSN305'!A1", "CSN305") | B11: Virtualization and Cloud Infrastructure | C11: 3 | D11: ='CSN305'!A6 | E11: ='CSN305'!C6 | F11: =IF('CSN305'!A6>0, 'CSN305'!E6, "--") | G11: A | H11: =IF(G11="A+", 0.90, IF(G11="A", 0.80, IF(G11="B+", 0.75, IF(G11="B", 0.70, IF(G11="C+", 0.65, IF(G11="C", 0.60, IF(G11="D+", 0.55, IF(G11="D", 0.50, 0.50)))))))) | I11: =1.0-D11 | J11: =IF(I11<=0, "Finished", (H11-E11)/I11) | K11: =IF(I11<=0, "Course Completed", IF(J11<=0, "✅ Secured", IF(J11>1.0, "❌ Impossible (>100%)", IF(J11>=0.85, "⚠️ Challenging (>=85%)", "✅ Achievable"))))
A12: =HYPERLINK("#'DAT330'!A1", "DAT330") | B12: Introduction to Databases | C12: 3 | D12: ='DAT330'!A6 | E12: ='DAT330'!C6 | F12: =IF('DAT330'!A6>0, 'DAT330'!E6, "--") | G12: A | H12: =IF(G12="A+", 0.90, IF(G12="A", 0.80, IF(G12="B+", 0.75, IF(G12="B", 0.70, IF(G12="C+", 0.65, IF(G12="C", 0.60, IF(G12="D+", 0.55, IF(G12="D", 0.50, 0.50)))))))) | I12: =1.0-D12 | J12: =IF(I12<=0, "Finished", (H12-E12)/I12) | K12: =IF(I12<=0, "Course Completed", IF(J12<=0, "✅ Secured", IF(J12>1.0, "❌ Impossible (>100%)", IF(J12>=0.85, "⚠️ Challenging (>=85%)", "✅ Achievable"))))
A13: =HYPERLINK("#'MST300'!A1", "MST300") | B13: Introduction to Microsoft Cloud Technologies | C13: 3 | D13: ='MST300'!A6 | E13: ='MST300'!C6 | F13: =IF('MST300'!A6>0, 'MST300'!E6, "--") | G13: A | H13: =IF(G13="A+", 0.90, IF(G13="A", 0.80, IF(G13="B+", 0.75, IF(G13="B", 0.70, IF(G13="C+", 0.65, IF(G13="C", 0.60, IF(G13="D+", 0.55, IF(G13="D", 0.50, 0.50)))))))) | I13: =1.0-D13 | J13: =IF(I13<=0, "Finished", (H13-E13)/I13) | K13: =IF(I13<=0, "Course Completed", IF(J13<=0, "✅ Secured", IF(J13>1.0, "❌ Impossible (>100%)", IF(J13>=0.85, "⚠️ Challenging (>=85%)", "✅ Achievable"))))
A14: =HYPERLINK("#'PSY262'!A1", "PSY262") | B14: Applied Psychology of Mindfulness | C14: 3 | D14: ='PSY262'!A6 | E14: ='PSY262'!C6 | F14: =IF('PSY262'!A6>0, 'PSY262'!E6, "--") | G14: A | H14: =IF(G14="A+", 0.90, IF(G14="A", 0.80, IF(G14="B+", 0.75, IF(G14="B", 0.70, IF(G14="C+", 0.65, IF(G14="C", 0.60, IF(G14="D+", 0.55, IF(G14="D", 0.50, 0.50)))))))) | I14: =1.0-D14 | J14: =IF(I14<=0, "Finished", (H14-E14)/I14) | K14: =IF(I14<=0, "Course Completed", IF(J14<=0, "✅ Secured", IF(J14>1.0, "❌ Impossible (>100%)", IF(J14>=0.85, "⚠️ Challenging (>=85%)", "✅ Achievable"))))
A15: =HYPERLINK("#'SEC320'!A1", "SEC320") | B15: Incident Response and Computer Forensics | C15: 3 | D15: ='SEC320'!A6 | E15: ='SEC320'!C6 | F15: =IF('SEC320'!A6>0, 'SEC320'!E6, "--") | G15: A | H15: =IF(G15="A+", 0.90, IF(G15="A", 0.80, IF(G15="B+", 0.75, IF(G15="B", 0.70, IF(G15="C+", 0.65, IF(G15="C", 0.60, IF(G15="D+", 0.55, IF(G15="D", 0.50, 0.50)))))))) | I15: =1.0-D15 | J15: =IF(I15<=0, "Finished", (H15-E15)/I15) | K15: =IF(I15<=0, "Course Completed", IF(J15<=0, "✅ Secured", IF(J15>1.0, "❌ Impossible (>100%)", IF(J15>=0.85, "⚠️ Challenging (>=85%)", "✅ Achievable"))))
A16: =HYPERLINK("#'OPS345'!A1", "OPS345") | B16: Open System Application Server | C16: 3 | D16: ='OPS345'!A6 | E16: ='OPS345'!C6 | F16: =IF('OPS345'!A6>0, 'OPS345'!E6, "--") | G16: A | H16: =IF(G16="A+", 0.90, IF(G16="A", 0.80, IF(G16="B+", 0.75, IF(G16="B", 0.70, IF(G16="C+", 0.65, IF(G16="C", 0.60, IF(G16="D+", 0.55, IF(G16="D", 0.50, 0.50)))))))) | I16: =1.0-D16 | J16: =IF(I16<=0, "Finished", (H16-E16)/I16) | K16: =IF(I16<=0, "Course Completed", IF(J16<=0, "✅ Secured", IF(J16>1.0, "❌ Impossible (>100%)", IF(J16>=0.85, "⚠️ Challenging (>=85%)", "✅ Achievable"))))

Sheet Timeline & Milestones
A1: Semester 3 Deliverables Chronological Timeline & Milestone Tracker | F1: =HYPERLINK("#'Dashboard & GPA'!A1", "⬅ Back to Dashboard")
A2: Master schedule of 110+ assignments, lab exercises, quizzes, midterms, and final exams sorted chronologically
A3: 💡 JUMP TO COURSE: Click 'Open Sheet ➔' on any deliverable to navigate directly to that course sheet.
A5: Course | B5: Assessment Deliverable | C5: Evaluation Category | D5: Weight % | E5: Scheduled Due Date | F5: Current Status | G5: Quick Link
A6: WTP100 | B6: Module 1 | C6: Modules & Knowledge Checks | D6: 0.0714 | E6: 2026-9-11 | F6: Done | G6: =HYPERLINK("#'WTP100'!A1", "Open Sheet ➔")
A7: WTP100 | B7: Module 2 | C7: Modules & Knowledge Checks | D7: 0.0714 | E7: 2026-9-11 | F7: Done | G7: =HYPERLINK("#'WTP100'!A1", "Open Sheet ➔")
A8: WTP100 | B8: Module 3 | C8: Modules & Knowledge Checks | D8: 0.0714 | E8: 2026-9-11 | F8: In Progress | G8: =HYPERLINK("#'WTP100'!A1", "Open Sheet ➔")
A9: WTP100 | B9: Module 10 | C9: Modules & Knowledge Checks | D9: 0.0714 | E9: 2026-9-11 | F9: Done | G9: =HYPERLINK("#'WTP100'!A1", "Open Sheet ➔")
A10: WTP100 | B10: Module 11 | C10: Modules & Knowledge Checks | D10: 0.0714 | E10: 2026-9-11 | F10: Done | G10: =HYPERLINK("#'WTP100'!A1", "Open Sheet ➔")
A11: WTP100 | B11: Module 12 | C11: Modules & Knowledge Checks | D11: 0.0714 | E11: 2026-9-11 | F11: Done | G11: =HYPERLINK("#'WTP100'!A1", "Open Sheet ➔")
A12: WTP100 | B12: Module 13 | C12: Modules & Knowledge Checks | D12: 0.0714 | E12: 2026-9-11 | F12: Done | G12: =HYPERLINK("#'WTP100'!A1", "Open Sheet ➔")
A13: WTP100 | B13: Module 14 | C13: Modules & Knowledge Checks | D13: 0.0718 | E13: 2026-9-11 | F13: Done | G13: =HYPERLINK("#'WTP100'!A1", "Open Sheet ➔")
A14: CSN305 | B14: Lab 1 | C14: Labs | D14: 0.04 | E14: 2026-09-17 | F14: Not Started | G14: =HYPERLINK("#'CSN305'!A1", "Open Sheet ➔")
A15: CSN305 | B15: Lab 10 | C15: Labs | D15: 0.04 | E15: 2026-09-17 | F15: Not Started | G15: =HYPERLINK("#'CSN305'!A1", "Open Sheet ➔")
A16: DAT330 | B16: Lab 1 | C16: Labs | D16: 0.025 | E16: 2026-09-17 | F16: Done | G16: =HYPERLINK("#'DAT330'!A1", "Open Sheet ➔")
A17: PSY262 | B17: Assignment 1 | C17: In-Class Assignments | D17: 0.025 | E17: 2026-9-18 | F17: Not Started | G17: =HYPERLINK("#'PSY262'!A1", "Open Sheet ➔")
A18: PSY262 | B18: Assignment 2 | C18: In-Class Assignments | D18: 0.025 | E18: 2026-9-18 | F18: Not Started | G18: =HYPERLINK("#'PSY262'!A1", "Open Sheet ➔")
A19: PSY262 | B19: Assignment 10 | C19: In-Class Assignments | D19: 0.025 | E19: 2026-9-18 | F19: Not Started | G19: =HYPERLINK("#'PSY262'!A1", "Open Sheet ➔")
A20: SEC320 | B20: Lab 1 | C20: Labs | D20: 0.04 | E20: 2026-9-18 | F20: Not Started | G20: =HYPERLINK("#'SEC320'!A1", "Open Sheet ➔")
A21: SEC320 | B21: Lab 10 | C21: Labs | D21: 0.04 | E21: 2026-9-18 | F21: Not Started | G21: =HYPERLINK("#'SEC320'!A1", "Open Sheet ➔")
A22: WTP100 | B22: Module 4 | C22: Modules & Knowledge Checks | D22: 0.0714 | E22: 2026-9-18 | F22: Not Started | G22: =HYPERLINK("#'WTP100'!A1", "Open Sheet ➔")
A23: WTP100 | B23: Module 5 | C23: Modules & Knowledge Checks | D23: 0.0714 | E23: 2026-9-18 | F23: Not Started | G23: =HYPERLINK("#'WTP100'!A1", "Open Sheet ➔")
A24: DAT330 | B24: Quiz 1 | C24: Quizzes | D24: 0.02 | E24: 2026-09-21 | F24: Not Started | G24: =HYPERLINK("#'DAT330'!A1", "Open Sheet ➔")
A25: MST300 | B25: Quiz 1 | C25: Quizzes | D25: 0.025 | E25: 2026-9-22 | F25: Not Started | G25: =HYPERLINK("#'MST300'!A1", "Open Sheet ➔")
A26: CSN305 | B26: Lab 2 | C26: Labs | D26: 0.04 | E26: 2026-09-24 | F26: Not Started | G26: =HYPERLINK("#'CSN305'!A1", "Open Sheet ➔")
A27: DAT330 | B27: Lab 2 | C27: Labs | D27: 0.025 | E27: 2026-09-24 | F27: Not Started | G27: =HYPERLINK("#'DAT330'!A1", "Open Sheet ➔")
A28: PSY262 | B28: Assignment 3 | C28: In-Class Assignments | D28: 0.025 | E28: 2026-9-25 | F28: Not Started | G28: =HYPERLINK("#'PSY262'!A1", "Open Sheet ➔")
A29: SEC320 | B29: Lab 2 | C29: Labs | D29: 0.04 | E29: 2026-9-25 | F29: Not Started | G29: =HYPERLINK("#'SEC320'!A1", "Open Sheet ➔")
A30: WTP100 | B30: Module 6 | C30: Modules & Knowledge Checks | D30: 0.0714 | E30: 2026-9-25 | F30: Not Started | G30: =HYPERLINK("#'WTP100'!A1", "Open Sheet ➔")
A31: WTP100 | B31: Module 7 | C31: Modules & Knowledge Checks | D31: 0.0714 | E31: 2026-9-25 | F31: Not Started | G31: =HYPERLINK("#'WTP100'!A1", "Open Sheet ➔")
A32: DAT330 | B32: Quiz 2 | C32: Quizzes | D32: 0.02 | E32: 2026-09-28 | F32: Not Started | G32: =HYPERLINK("#'DAT330'!A1", "Open Sheet ➔")
A33: CSN305 | B33: Lab 3 | C33: Labs | D33: 0.04 | E33: 2026-10-01 | F33: Not Started | G33: =HYPERLINK("#'CSN305'!A1", "Open Sheet ➔")
A34: CSN305 | B34: Test 1 | C34: Tests | D34: 0.15 | E34: 2026-10-01 | F34: Not Started | G34: =HYPERLINK("#'CSN305'!A1", "Open Sheet ➔")
A35: DAT330 | B35: Assignment 1 | C35: Assignments | D35: 0.05 | E35: 2026-10-01 | F35: Not Started | G35: =HYPERLINK("#'DAT330'!A1", "Open Sheet ➔")
A36: PSY262 | B36: Assignment 4 | C36: In-Class Assignments | D36: 0.025 | E36: 2026-10-02 | F36: Not Started | G36: =HYPERLINK("#'PSY262'!A1", "Open Sheet ➔")
A37: PSY262 | B37: Quiz 1 | C37: Quiz 1 | D37: 0.2 | E37: 2026-10-02 | F37: Not Started | G37: =HYPERLINK("#'PSY262'!A1", "Open Sheet ➔")
A38: SEC320 | B38: Lab 3 | C38: Labs | D38: 0.04 | E38: 2026-10-2 | F38: Not Started | G38: =HYPERLINK("#'SEC320'!A1", "Open Sheet ➔")
A39: WTP100 | B39: Module 8 | C39: Modules & Knowledge Checks | D39: 0.0714 | E39: 2026-10-02 | F39: Not Started | G39: =HYPERLINK("#'WTP100'!A1", "Open Sheet ➔")
A40: WTP100 | B40: Module 9 | C40: Modules & Knowledge Checks | D40: 0.0714 | E40: 2026-10-02 | F40: Not Started | G40: =HYPERLINK("#'WTP100'!A1", "Open Sheet ➔")
A41: MST300 | B41: Lab 2 | C41: Labs | D41: 0.0333 | E41: 2026-10-6 | F41: Not Started | G41: =HYPERLINK("#'MST300'!A1", "Open Sheet ➔")
...
